<robot name = "robot">
    <link name="Head">
        <inertial>
            <origin xyz="0 0 2" rpy="0 0 0"/>
            <mass value="1" />
            <inertia ixx="100" ixy="0" ixz="0" iyy="100" iyz="0" izz="100" />
        </inertial>
        <visual>
            <origin xyz="0 0 2" rpy="0 0 0"/>
            <geometry>
                <box size="1 1 1" />
            </geometry>
            <material name="Green">
                <color rgba="0 1.0 0 1.0"/>
            </material>
        </visual>
        <collision>
            <origin xyz="0 0 2" rpy="0 0 0"/>
            <geometry>
                <box size="1 1 1" />
            </geometry>
        </collision>
    </link>
    <joint name="Head_Link0" type="fixed">
       <parent link="Head"/>
       <child  link="Link0"/>
       <origin rpy="0 0 0" xyz="0 0 1" />
     <axis xyz="1 0 1"/>
       <limit effort="0.0" lower="-3.14159" upper="3.14159" velocity="0.0"/>
    </joint>
    <link name="Link0">
        <inertial>
            <origin xyz="0 0 0" rpy="0 0 0"/>
            <mass value="1" />
            <inertia ixx="100" ixy="0" ixz="0" iyy="100" iyz="0" izz="100" />
        </inertial>
        <visual>
            <origin xyz="0 0 0" rpy="0 0 0"/>
            <geometry>
                <box size="1 1 1" />
            </geometry>
            <material name="Cyan">
                <color rgba="0 1.0 1.0 1.0"/>
            </material>
        </visual>
        <collision>
            <origin xyz="0 0 0" rpy="0 0 0"/>
            <geometry>
                <box size="1 1 1" />
            </geometry>
        </collision>
    </link>
    <joint name="Link0_Link0Right" type="revolute">
       <parent link="Link0"/>
       <child  link="Link0Right"/>
       <origin rpy="0 0 0" xyz="0 0 0" />
     <axis xyz="0 1 1"/>
       <limit effort="0.0" lower="-3.14159" upper="3.14159" velocity="0.0"/>
    </joint>
    <link name="Link0Right">
        <inertial>
            <origin xyz="1 0 0" rpy="0 0 0"/>
            <mass value="1" />
            <inertia ixx="100" ixy="0" ixz="0" iyy="100" iyz="0" izz="100" />
        </inertial>
        <visual>
            <origin xyz="1 0 0" rpy="0 0 0"/>
            <geometry>
                <box size="1 0.16666666666666666 0.16666666666666666" />
            </geometry>
            <material name="Cyan">
                <color rgba="0 1.0 1.0 1.0"/>
            </material>
        </visual>
        <collision>
            <origin xyz="1 0 0" rpy="0 0 0"/>
            <geometry>
                <box size="1 0.16666666666666666 0.16666666666666666" />
            </geometry>
        </collision>
    </link>
    <joint name="Link0_Link0Left" type="revolute">
       <parent link="Link0"/>
       <child  link="Link0Left"/>
       <origin rpy="0 0 0" xyz="0 0 0" />
     <axis xyz="0 1 1"/>
       <limit effort="0.0" lower="-3.14159" upper="3.14159" velocity="0.0"/>
    </joint>
    <link name="Link0Left">
        <inertial>
            <origin xyz="-1 0 0" rpy="0 0 0"/>
            <mass value="1" />
            <inertia ixx="100" ixy="0" ixz="0" iyy="100" iyz="0" izz="100" />
        </inertial>
        <visual>
            <origin xyz="-1 0 0" rpy="0 0 0"/>
            <geometry>
                <box size="1 0.16666666666666666 0.16666666666666666" />
            </geometry>
            <material name="Cyan">
                <color rgba="0 1.0 1.0 1.0"/>
            </material>
        </visual>
        <collision>
            <origin xyz="-1 0 0" rpy="0 0 0"/>
            <geometry>
                <box size="1 0.16666666666666666 0.16666666666666666" />
            </geometry>
        </collision>
    </link>
    <joint name="Link0Right_Link0RightFoot" type="fixed">
       <parent link="Link0Right"/>
       <child  link="Link0RightFoot"/>
       <origin rpy="0 0 0" xyz="1 0 0.5" />
     <axis xyz="1 0 1"/>
       <limit effort="0.0" lower="-3.14159" upper="3.14159" velocity="0.0"/>
    </joint>
    <link name="Link0RightFoot">
        <inertial>
            <origin xyz="0.5 0 -1" rpy="0 0 0"/>
            <mass value="1" />
            <inertia ixx="100" ixy="0" ixz="0" iyy="100" iyz="0" izz="100" />
        </inertial>
        <visual>
            <origin xyz="0.5 0 -1" rpy="0 0 0"/>
            <geometry>
                <box size="0.16666666666666666 0.16666666666666666 1" />
            </geometry>
            <material name="Green">
                <color rgba="0 1.0 0 1.0"/>
            </material>
        </visual>
        <collision>
            <origin xyz="0.5 0 -1" rpy="0 0 0"/>
            <geometry>
                <box size="0.16666666666666666 0.16666666666666666 1" />
            </geometry>
        </collision>
    </link>
    <joint name="Link0Left_Link0LeftFoot" type="fixed">
       <parent link="Link0Left"/>
       <child  link="Link0LeftFoot"/>
       <origin rpy="0 0 0" xyz="1 0 0.5" />
     <axis xyz="1 0 1"/>
       <limit effort="0.0" lower="-3.14159" upper="3.14159" velocity="0.0"/>
    </joint>
    <link name="Link0LeftFoot">
        <inertial>
            <origin xyz="-2.5 0 -1" rpy="0 0 0"/>
            <mass value="1" />
            <inertia ixx="100" ixy="0" ixz="0" iyy="100" iyz="0" izz="100" />
        </inertial>
        <visual>
            <origin xyz="-2.5 0 -1" rpy="0 0 0"/>
            <geometry>
                <box size="0.16666666666666666 0.16666666666666666 1" />
            </geometry>
            <material name="Green">
                <color rgba="0 1.0 0 1.0"/>
            </material>
        </visual>
        <collision>
            <origin xyz="-2.5 0 -1" rpy="0 0 0"/>
            <geometry>
                <box size="0.16666666666666666 0.16666666666666666 1" />
            </geometry>
        </collision>
    </link>
    <joint name="Link0_Link1" type="fixed">
       <parent link="Link0"/>
       <child  link="Link1"/>
       <origin rpy="0 0 0" xyz="0 1 0" />
     <axis xyz="0 1 0"/>
       <limit effort="0.0" lower="-3.14159" upper="3.14159" velocity="0.0"/>
    </joint>
    <link name="Link1">
        <inertial>
            <origin xyz="0 0 0" rpy="0 0 0"/>
            <mass value="1" />
            <inertia ixx="100" ixy="0" ixz="0" iyy="100" iyz="0" izz="100" />
        </inertial>
        <visual>
            <origin xyz="0 0 0" rpy="0 0 0"/>
            <geometry>
                <box size="1 1 1" />
            </geometry>
            <material name="Cyan">
                <color rgba="0 1.0 1.0 1.0"/>
            </material>
        </visual>
        <collision>
            <origin xyz="0 0 0" rpy="0 0 0"/>
            <geometry>
                <box size="1 1 1" />
            </geometry>
        </collision>
    </link>
    <joint name="Link1_Link1Right" type="revolute">
       <parent link="Link1"/>
       <child  link="Link1Right"/>
       <origin rpy="0 0 0" xyz="0 0 0" />
     <axis xyz="0 1 1"/>
       <limit effort="0.0" lower="-3.14159" upper="3.14159" velocity="0.0"/>
    </joint>
    <link name="Link1Right">
        <inertial>
            <origin xyz="1 0 0" rpy="0 0 0"/>
            <mass value="1" />
            <inertia ixx="100" ixy="0" ixz="0" iyy="100" iyz="0" izz="100" />
        </inertial>
        <visual>
            <origin xyz="1 0 0" rpy="0 0 0"/>
            <geometry>
                <box size="1 0.16666666666666666 0.16666666666666666" />
            </geometry>
            <material name="Cyan">
                <color rgba="0 1.0 1.0 1.0"/>
            </material>
        </visual>
        <collision>
            <origin xyz="1 0 0" rpy="0 0 0"/>
            <geometry>
                <box size="1 0.16666666666666666 0.16666666666666666" />
            </geometry>
        </collision>
    </link>
    <joint name="Link1_Link1Left" type="revolute">
       <parent link="Link1"/>
       <child  link="Link1Left"/>
       <origin rpy="0 0 0" xyz="0 0 0" />
     <axis xyz="0 1 1"/>
       <limit effort="0.0" lower="-3.14159" upper="3.14159" velocity="0.0"/>
    </joint>
    <link name="Link1Left">
        <inertial>
            <origin xyz="-1 0 0" rpy="0 0 0"/>
            <mass value="1" />
            <inertia ixx="100" ixy="0" ixz="0" iyy="100" iyz="0" izz="100" />
        </inertial>
        <visual>
            <origin xyz="-1 0 0" rpy="0 0 0"/>
            <geometry>
                <box size="1 0.16666666666666666 0.16666666666666666" />
            </geometry>
            <material name="Cyan">
                <color rgba="0 1.0 1.0 1.0"/>
            </material>
        </visual>
        <collision>
            <origin xyz="-1 0 0" rpy="0 0 0"/>
            <geometry>
                <box size="1 0.16666666666666666 0.16666666666666666" />
            </geometry>
        </collision>
    </link>
    <joint name="Link1Right_Link1RightFoot" type="fixed">
       <parent link="Link1Right"/>
       <child  link="Link1RightFoot"/>
       <origin rpy="0 0 0" xyz="1 0 0.5" />
     <axis xyz="1 0 1"/>
       <limit effort="0.0" lower="-3.14159" upper="3.14159" velocity="0.0"/>
    </joint>
    <link name="Link1RightFoot">
        <inertial>
            <origin xyz="0.5 0 -1" rpy="0 0 0"/>
            <mass value="1" />
            <inertia ixx="100" ixy="0" ixz="0" iyy="100" iyz="0" izz="100" />
        </inertial>
        <visual>
            <origin xyz="0.5 0 -1" rpy="0 0 0"/>
            <geometry>
                <box size="0.16666666666666666 0.16666666666666666 1" />
            </geometry>
            <material name="Green">
                <color rgba="0 1.0 0 1.0"/>
            </material>
        </visual>
        <collision>
            <origin xyz="0.5 0 -1" rpy="0 0 0"/>
            <geometry>
                <box size="0.16666666666666666 0.16666666666666666 1" />
            </geometry>
        </collision>
    </link>
    <joint name="Link1Left_Link1LeftFoot" type="fixed">
       <parent link="Link1Left"/>
       <child  link="Link1LeftFoot"/>
       <origin rpy="0 0 0" xyz="1 0 0.5" />
     <axis xyz="1 0 1"/>
       <limit effort="0.0" lower="-3.14159" upper="3.14159" velocity="0.0"/>
    </joint>
    <link name="Link1LeftFoot">
        <inertial>
            <origin xyz="-2.5 0 -1" rpy="0 0 0"/>
            <mass value="1" />
            <inertia ixx="100" ixy="0" ixz="0" iyy="100" iyz="0" izz="100" />
        </inertial>
        <visual>
            <origin xyz="-2.5 0 -1" rpy="0 0 0"/>
            <geometry>
                <box size="0.16666666666666666 0.16666666666666666 1" />
            </geometry>
            <material name="Green">
                <color rgba="0 1.0 0 1.0"/>
            </material>
        </visual>
        <collision>
            <origin xyz="-2.5 0 -1" rpy="0 0 0"/>
            <geometry>
                <box size="0.16666666666666666 0.16666666666666666 1" />
            </geometry>
        </collision>
    </link>
    <joint name="Link1_Link2" type="fixed">
       <parent link="Link1"/>
       <child  link="Link2"/>
       <origin rpy="0 0 0" xyz="0 1 0" />
     <axis xyz="0 1 0"/>
       <limit effort="0.0" lower="-3.14159" upper="3.14159" velocity="0.0"/>
    </joint>
    <link name="Link2">
        <inertial>
            <origin xyz="0 0 0" rpy="0 0 0"/>
            <mass value="1" />
            <inertia ixx="100" ixy="0" ixz="0" iyy="100" iyz="0" izz="100" />
        </inertial>
        <visual>
            <origin xyz="0 0 0" rpy="0 0 0"/>
            <geometry>
                <box size="1 1 1" />
            </geometry>
            <material name="Cyan">
                <color rgba="0 1.0 1.0 1.0"/>
            </material>
        </visual>
        <collision>
            <origin xyz="0 0 0" rpy="0 0 0"/>
            <geometry>
                <box size="1 1 1" />
            </geometry>
        </collision>
    </link>
    <joint name="Link2_Link2Right" type="revolute">
       <parent link="Link2"/>
       <child  link="Link2Right"/>
       <origin rpy="0 0 0" xyz="0 0 0" />
     <axis xyz="0 1 1"/>
       <limit effort="0.0" lower="-3.14159" upper="3.14159" velocity="0.0"/>
    </joint>
    <link name="Link2Right">
        <inertial>
            <origin xyz="1 0 0" rpy="0 0 0"/>
            <mass value="1" />
            <inertia ixx="100" ixy="0" ixz="0" iyy="100" iyz="0" izz="100" />
        </inertial>
        <visual>
            <origin xyz="1 0 0" rpy="0 0 0"/>
            <geometry>
                <box size="1 0.16666666666666666 0.16666666666666666" />
            </geometry>
            <material name="Cyan">
                <color rgba="0 1.0 1.0 1.0"/>
            </material>
        </visual>
        <collision>
            <origin xyz="1 0 0" rpy="0 0 0"/>
            <geometry>
                <box size="1 0.16666666666666666 0.16666666666666666" />
            </geometry>
        </collision>
    </link>
    <joint name="Link2_Link2Left" type="revolute">
       <parent link="Link2"/>
       <child  link="Link2Left"/>
       <origin rpy="0 0 0" xyz="0 0 0" />
     <axis xyz="0 1 1"/>
       <limit effort="0.0" lower="-3.14159" upper="3.14159" velocity="0.0"/>
    </joint>
    <link name="Link2Left">
        <inertial>
            <origin xyz="-1 0 0" rpy="0 0 0"/>
            <mass value="1" />
            <inertia ixx="100" ixy="0" ixz="0" iyy="100" iyz="0" izz="100" />
        </inertial>
        <visual>
            <origin xyz="-1 0 0" rpy="0 0 0"/>
            <geometry>
                <box size="1 0.16666666666666666 0.16666666666666666" />
            </geometry>
            <material name="Cyan">
                <color rgba="0 1.0 1.0 1.0"/>
            </material>
        </visual>
        <collision>
            <origin xyz="-1 0 0" rpy="0 0 0"/>
            <geometry>
                <box size="1 0.16666666666666666 0.16666666666666666" />
            </geometry>
        </collision>
    </link>
    <joint name="Link2Right_Link2RightFoot" type="fixed">
       <parent link="Link2Right"/>
       <child  link="Link2RightFoot"/>
       <origin rpy="0 0 0" xyz="1 0 0.5" />
     <axis xyz="1 0 1"/>
       <limit effort="0.0" lower="-3.14159" upper="3.14159" velocity="0.0"/>
    </joint>
    <link name="Link2RightFoot">
        <inertial>
            <origin xyz="0.5 0 -1" rpy="0 0 0"/>
            <mass value="1" />
            <inertia ixx="100" ixy="0" ixz="0" iyy="100" iyz="0" izz="100" />
        </inertial>
        <visual>
            <origin xyz="0.5 0 -1" rpy="0 0 0"/>
            <geometry>
                <box size="0.16666666666666666 0.16666666666666666 1" />
            </geometry>
            <material name="Green">
                <color rgba="0 1.0 0 1.0"/>
            </material>
        </visual>
        <collision>
            <origin xyz="0.5 0 -1" rpy="0 0 0"/>
            <geometry>
                <box size="0.16666666666666666 0.16666666666666666 1" />
            </geometry>
        </collision>
    </link>
    <joint name="Link2Left_Link2LeftFoot" type="fixed">
       <parent link="Link2Left"/>
       <child  link="Link2LeftFoot"/>
       <origin rpy="0 0 0" xyz="1 0 0.5" />
     <axis xyz="1 0 1"/>
       <limit effort="0.0" lower="-3.14159" upper="3.14159" velocity="0.0"/>
    </joint>
    <link name="Link2LeftFoot">
        <inertial>
            <origin xyz="-2.5 0 -1" rpy="0 0 0"/>
            <mass value="1" />
            <inertia ixx="100" ixy="0" ixz="0" iyy="100" iyz="0" izz="100" />
        </inertial>
        <visual>
            <origin xyz="-2.5 0 -1" rpy="0 0 0"/>
            <geometry>
                <box size="0.16666666666666666 0.16666666666666666 1" />
            </geometry>
            <material name="Green">
                <color rgba="0 1.0 0 1.0"/>
            </material>
        </visual>
        <collision>
            <origin xyz="-2.5 0 -1" rpy="0 0 0"/>
            <geometry>
                <box size="0.16666666666666666 0.16666666666666666 1" />
            </geometry>
        </collision>
    </link>
</robot>